Workbook

Sheet Pivot Table
A3: Row Labels | B3: Average of Performance(0 - 100 )KM/H | C3: Count of Fuel Types | D3: Average of Horse Power Final | E3: Average of Car Prices Final | F3: Average of Seats | G3: Median of Car Prices Final | I3: Car Lookup
A4: Acura | B4: 5.6777778 | C4: 27 | D4: 311.03704 | E4: 63259.259 | F4: 5 | G4: {=MEDIAN(IF('Cars Datasets 2025'!$A$2:$A$1203=$A4,'Cars Datasets 2025'!$H$2:$H$1203))} -> 50000 | I4: Car Name (input) | J4: 911 GT3 RS
A5: Aston Martin | B5: 3.5272727 | C5: 11 | D5: 701.09091 | E5: 752949.09 | F5: 2.8181818 | G5: {=MEDIAN(IF('Cars Datasets 2025'!$A$2:$A$1203=$A5,'Cars Datasets 2025'!$H$2:$H$1203))} -> 294000 | I5: Engine | J5: =IFERROR(VLOOKUP($J$4,'Cars Datasets 2025'!$B$2:$K$1203,2,FALSE),"Not found") -> 4.0L Naturally Aspirated Flat-6
A6: Audi | B6: 5.1619048 | C6: 21 | D6: 393.19048 | E6: 82870.952 | F6: 4.5714286 | G6: {=MEDIAN(IF('Cars Datasets 2025'!$A$2:$A$1203=$A6,'Cars Datasets 2025'!$H$2:$H$1203))} -> 64000 | I6: CC / Battery Capacity | J6: =IFERROR(VLOOKUP($J$4,'Cars Datasets 2025'!$B$2:$K$1203,3,FALSE),"Not found") -> 3996
A7: Bentley | B7: 4 | C7: 1 | D7: 550 | E7: 311000 | F7: 4 | G7: {=MEDIAN(IF('Cars Datasets 2025'!$A$2:$A$1203=$A7,'Cars Datasets 2025'!$H$2:$H$1203))} -> 311000 | I7: Horse Power | J7: =IFERROR(VLOOKUP($J$4,'Cars Datasets 2025'!$B$2:$K$1203,4,FALSE),"Not found") -> 518
A8: Bmw | B8: 6.8804878 | C8: 41 | D8: 274.53659 | E8: 67317.073 | F8: 4.7317073 | G8: {=MEDIAN(IF('Cars Datasets 2025'!$A$2:$A$1203=$A8,'Cars Datasets 2025'!$H$2:$H$1203))} -> 39000 | I8: Total Speed (km/h) | J8: =IFERROR(VLOOKUP($J$4,'Cars Datasets 2025'!$B$2:$K$1203,5,FALSE),"Not found") -> 296
A9: Bugatti | B9: 2.4 | C9: 10 | D9: 1565 | E9: 5870000 | F9: 2 | G9: {=MEDIAN(IF('Cars Datasets 2025'!$A$2:$A$1203=$A9,'Cars Datasets 2025'!$H$2:$H$1203))} -> 4000000 | I9: 0-100 km/h (sec) | J9: =IFERROR(VLOOKUP($J$4,'Cars Datasets 2025'!$B$2:$K$1203,6,FALSE),"Not found") -> 3.2
A10: Cadillac | B10: 5.94 | C10: 20 | D10: 368.4 | E10: 62178.5 | F10: 5.6 | G10: {=MEDIAN(IF('Cars Datasets 2025'!$A$2:$A$1203=$A10,'Cars Datasets 2025'!$H$2:$H$1203))} -> 54095 | I10: Price ($) | J10: =IFERROR(VLOOKUP($J$4,'Cars Datasets 2025'!$B$2:$K$1203,7,FALSE),"Not found") -> 241300
A11: Chevrolet | B11: 7.3285714 | C11: 56 | D11: 303.71429 | E11: 44808.036 | F11: 5.6428571 | G11: {=MEDIAN(IF('Cars Datasets 2025'!$A$2:$A$1203=$A11,'Cars Datasets 2025'!$H$2:$H$1203))} -> 43600 | I11: Fuel Type | J11: =IFERROR(VLOOKUP($J$4,'Cars Datasets 2025'!$B$2:$K$1203,8,FALSE),"Not found") -> Petrol
A12: Ferrari | B12: 3.0333333 | C12: 9 | D12: 709.88889 | E12: 512222.22 | F12: 2.8888889 | G12: {=MEDIAN(IF('Cars Datasets 2025'!$A$2:$A$1203=$A12,'Cars Datasets 2025'!$H$2:$H$1203))} -> 280000 | I12: Seats | J12: =IFERROR(VLOOKUP($J$4,'Cars Datasets 2025'!$B$2:$K$1203,9,FALSE),"Not found") -> 2
A13: Ford | B13: 7.4 | C13: 53 | D13: 319.41509 | E13: 54211.604 | F13: 5.490566 | G13: {=MEDIAN(IF('Cars Datasets 2025'!$A$2:$A$1203=$A13,'Cars Datasets 2025'!$H$2:$H$1203))} -> 45000 | I13: Torque | J13: =IFERROR(VLOOKUP($J$4,'Cars Datasets 2025'!$B$2:$K$1203,10,FALSE),"Not found") -> 465
A14: Gmc | B14: 6.8542373 | C14: 59 | D14: 344.71698 | E14: 63293.475 | F14: 5.779661 | G14: {=MEDIAN(IF('Cars Datasets 2025'!$A$2:$A$1203=$A14,'Cars Datasets 2025'!$H$2:$H$1203))} -> 60000 | I14: Company | J14: =IFERROR(INDEX('Cars Datasets 2025'!$A$2:$A$1203,MATCH($J$4,'Cars Datasets 2025'!$B$2:$B$1203,0)),"Not found") -> Porsche
A15: Honda | B15: 7.5428571 | C15: 7 | D15: 205.57143 | E15: 29364.286 | F15: 5.4285714 | G15: {=MEDIAN(IF('Cars Datasets 2025'!$A$2:$A$1203=$A15,'Cars Datasets 2025'!$H$2:$H$1203))} -> 29400
A16: Hyundai | B16: 7.8545455 | C16: 23 | D16: 198.17391 | E16: 31495.609 | F16: 5.0869565 | G16: {=MEDIAN(IF('Cars Datasets 2025'!$A$2:$A$1203=$A16,'Cars Datasets 2025'!$H$2:$H$1203))} -> 25000 | I16: Brand Lookup
A17: Jaguar Land Rover | B17: 5.3461538 | C17: 40 | D17: 357.20513 | E17: 72435.897 | F17: 4.25 | G17: {=MEDIAN(IF('Cars Datasets 2025'!$A$2:$A$1203=$A17,'Cars Datasets 2025'!$H$2:$H$1203))} -> 67500 | I17: Brand (input) | J17: Toyota
A18: Jeep | B18: 7.0684211 | C18: 19 | D18: 318.89474 | E18: 51439.211 | F18: 5.2631579 | G18: {=MEDIAN(IF('Cars Datasets 2025'!$A$2:$A$1203=$A18,'Cars Datasets 2025'!$H$2:$H$1203))} -> 44500 | I18: Avg 0-100 km/h (sec) | J18: =IFERROR(VLOOKUP($J$17,$A$4:$G$34,2,FALSE),"Not found") -> 8.1545455
A19: Kia | B19: 7.8507042 | C19: 71 | D19: 216.28169 | E19: 36014.085 | F19: 5.5492958 | G19: {=MEDIAN(IF('Cars Datasets 2025'!$A$2:$A$1203=$A19,'Cars Datasets 2025'!$H$2:$H$1203))} -> 34500 | I19: Model Count | J19: =IFERROR(VLOOKUP($J$17,$A$4:$G$34,3,FALSE),"Not found") -> 49
A20: Lamborghini | B20: 3.0375 | C20: 24 | D20: 691.54167 | E20: 650083.33 | F20: 2.5 | G20: {=MEDIAN(IF('Cars Datasets 2025'!$A$2:$A$1203=$A20,'Cars Datasets 2025'!$H$2:$H$1203))} -> 334500 | I20: Avg Horse Power | J20: =IFERROR(VLOOKUP($J$17,$A$4:$G$34,4,FALSE),"Not found") -> 235.93478
A21: Mahindra | B21: 10.733333 | C21: 3 | D21: 148.33333 | E21: 18400 | F21: 6 | G21: {=MEDIAN(IF('Cars Datasets 2025'!$A$2:$A$1203=$A21,'Cars Datasets 2025'!$H$2:$H$1203))} -> 18400 | I21: Avg Price | J21: =IFERROR(VLOOKUP($J$17,$A$4:$G$34,5,FALSE),"Not found") -> 42876.333
A22: Maruti Suzuki | B22: 11.966667 | C22: 3 | D22: 89.666667 | E22: 12066.667 | F22: 5 | G22: {=MEDIAN(IF('Cars Datasets 2025'!$A$2:$A$1203=$A22,'Cars Datasets 2025'!$H$2:$H$1203))} -> 11400 | I22: Avg Seats | J22: =IFERROR(VLOOKUP($J$17,$A$4:$G$34,6,FALSE),"Not found") -> 5.5918367
A23: Mazda | B23: 10.419767 | C23: 87 | D23: 154.68605 | E23: 93825.581 | F23: 4.4137931 | G23: {=MEDIAN(IF('Cars Datasets 2025'!$A$2:$A$1203=$A23,'Cars Datasets 2025'!$H$2:$H$1203))} -> 22500 | I23: Median Price | J23: =IFERROR(VLOOKUP($J$17,$A$4:$G$34,7,FALSE),"Not found") -> 38400
A24: Mercedes | B24: 4.7571429 | C24: 21 | D24: 432.85714 | E24: 84190.476 | F24: 4.952381 | G24: {=MEDIAN(IF('Cars Datasets 2025'!$A$2:$A$1203=$A24,'Cars Datasets 2025'!$H$2:$H$1203))} -> 70000
A25: Mitsubishi | B25: 11.038182 | C25: 60 | D25: 147.3 | E25: 28850 | F25: 5.35 | G25: {=MEDIAN(IF('Cars Datasets 2025'!$A$2:$A$1203=$A25,'Cars Datasets 2025'!$H$2:$H$1203))} -> 27500
A26: Nissan | B26: 8.5407643 | C26: 157 | D26: 311.36364 | E26: 59674.777 | F26: 5.0254777 | G26: {=MEDIAN(IF('Cars Datasets 2025'!$A$2:$A$1203=$A26,'Cars Datasets 2025'!$H$2:$H$1203))} -> 35000
A27: Peugeot | B27: 8.6735849 | C27: 53 | D27: 176.73585 | E27: 35047.17 | F27: 5.1132075 | G27: {=MEDIAN(IF('Cars Datasets 2025'!$A$2:$A$1203=$A27,'Cars Datasets 2025'!$H$2:$H$1203))} -> 35000
A28: Porsche | B28: 4.2120879 | C28: 91 | D28: 482.34286 | E28: 141291.21 | F28: 3.8131868 | G28: {=MEDIAN(IF('Cars Datasets 2025'!$A$2:$A$1203=$A28,'Cars Datasets 2025'!$H$2:$H$1203))} -> 116000
A29: Rolls Royce | B29: 4.91 | C29: 30 | D29: 584 | E29: 390400 | F29: 4.5333333 | G29: {=MEDIAN(IF('Cars Datasets 2025'!$A$2:$A$1203=$A29,'Cars Datasets 2025'!$H$2:$H$1203))} -> 377500
A30: Tata Motors | B30: 13.460714 | C30: 28 | D30: 98.869565 | E30: 12507.143 | F30: 5.3214286 | G30: {=MEDIAN(IF('Cars Datasets 2025'!$A$2:$A$1203=$A30,'Cars Datasets 2025'!$H$2:$H$1203))} -> 10750
A31: Tesla | B31: 3.51 | C31: 10 | D31: 693.1 | E31: 87032 | F31: 5.3 | G31: {=MEDIAN(IF('Cars Datasets 2025'!$A$2:$A$1203=$A31,'Cars Datasets 2025'!$H$2:$H$1203))} -> 79195
A32: Toyota | B32: 8.1545455 | C32: 49 | D32: 235.93478 | E32: 42876.333 | F32: 5.5918367 | G32: {=MEDIAN(IF('Cars Datasets 2025'!$A$2:$A$1203=$A32,'Cars Datasets 2025'!$H$2:$H$1203))} -> 38400
A33: Volkswagen | B33: 8.5216981 | C33: 106 | D33: 191.40952 | E33: 36592.783 | F33: 4.9339623 | G33: {=MEDIAN(IF('Cars Datasets 2025'!$A$2:$A$1203=$A33,'Cars Datasets 2025'!$H$2:$H$1203))} -> 33000
A34: Volvo | B34: 14.4 | C34: 12 | D34: 408.25 | E34: 97083.333 | F34: 2.9166667 | G34: {=MEDIAN(IF('Cars Datasets 2025'!$A$2:$A$1203=$A34,'Cars Datasets 2025'!$H$2:$H$1203))} -> 97500
A35: Grand Total | B35: 7.5801352 | C35: 1202 | D35: 311.20138 | E35: 139642.56 | F35: 4.8785358 | G35: =MEDIAN('Cars Datasets 2025'!$H$2:$H$1203) -> 42647.5

Sheet Cars Datasets 2025
A1: Company Names | B1: Cars Names | C1: Engines | D1: CC/Battery Capacity | E1: Horse Power Final | F1: Total Speed | G1: Performance(0 - 100 )KM/H | H1: Car Prices Final | I1: Fuel Types | J1: Seats | K1: Torque Final
A2: Bugatti | B2: La Voiture Noire | C2: 8.0L Quad-Turbo W16 | D2: 7993 | E2: 1500 | F2: 420 | G2: 2.5 | H2: 18000000 | I2: Petrol | J2: 2 | K2: 1600
A3: Bugatti | B3: Centodieci | C3: 8.0L Quad-Turbo W16 | D3: 7993 | E3: 1600 | F3: 380 | G3: 2.4 | H3: 9000000 | I3: Petrol | J3: 2 | K3: 1600
A4: Mazda | B4: 787B (Race Car) | C4: 2.6L Wankel Rotary Engine | D4: 2620 | E4: 700 | F4: 320 | G4: 3.5 | H4: 6000000 | I4: Petrol | J4: 1 | K4: 500
A5: Bugatti | B5: Divo | C5: 8.0L Quad-Turbo W16 | D5: 7993 | E5: 1500 | F5: 380 | G5: 2.4 | H5: 5800000 | I5: Petrol | J5: 2 | K5: 1600
A6: Bugatti | B6: Mistral | C6: 8.0L Quad-Turbo W16 | D6: 7993 | E6: 1600 | F6: 420 | G6: 2.4 | H6: 5000000 | I6: Petrol | J6: 2 | K6: 1600
A7: Bugatti | B7: Bolide | C7: 8.0L Quad-Turbo W16 | D7: 7993 | E7: 1850 | F7: 500 | G7: 2.2 | H7: 4500000 | I7: Petrol | J7: 2 | K7: 1600
A8: Lamborghini | B8: VENENO ROADSTER | C8: V12 | D8: 6498 | E8: 750 | F8: 356 | G8: 2.9 | H8: 4500000 | I8: Petrol | J8: 2 | K8: 690
A9: Bugatti | B9: Chiron Super Sport | C9: 8.0L Quad-Turbo W16 | D9: 7993 | E9: 1600 | F9: 490 | G9: 2.4 | H9: 3500000 | I9: Petrol | J9: 2 | K9: 1600
A10: Bugatti | B10: Chiron Pur Sport | C10: 8.0L Quad-Turbo W16 | D10: 7993 | E10: 1500 | F10: 350 | G10: 2.3 | H10: 3300000 | I10: Petrol | J10: 2 | K10: 1600
A11: Bugatti | B11: Chiron Sport | C11: 8.0L Quad-Turbo W16 | D11: 7993 | E11: 1500 | F11: 420 | G11: 2.4 | H11: 3300000 | I11: Petrol | J11: 2 | K11: 1600
A12: Bugatti | B12: Chiron Noire | C12: 8.0L Quad-Turbo W16 | D12: 7993 | E12: 1500 | F12: 420 | G12: 2.5 | H12: 3300000 | I12: Petrol | J12: 2 | K12: 1600
A13: Aston Martin | B13: VALKYRIE | C13: V12 | D13: 6496 | E13: 1160 | F13: 402 | G13: 2.5 | H13: 3200000 | I13: Hybrid | J13: 2 | K13: 900
... A20: Ferrari | B20: SF90 STRADALE | C20: V8 | D20: 3990 | E20: 963 | F20: 340 | G20: 2.5 | H20: 1100000 | I20: Plug-in Hybrid | J20: 2 | K20: 800
A21: Nissan | B21: GT-R50 by Italdesign | C21: 3.8L Twin-Turbo V6 | D21: 3799 | F21: 315 | G21: 2.5 | H21: 1100000 | I21: Petrol | J21: 2 | K21: 780
A22: Nissan | B22: R390 GT1 Road Car | C22: 3.5L Twin-Turbo V8 | D22: 3495 | F22: 354 | G22: 3.3 | H22: 1000000 | I22: Petrol | J22: 2 | K22: 637
A23: Porsche | B23: 911 RSR (Motorsport Edition) | C23: 4.2L Naturally Aspirated Flat-6 | D23: 4194 | E23: 515 | F23: 296 | G23: 3.1 | H23: 750000 | I23: Petrol | J23: 1 | K23: 480
A24: Lamborghini | B24: AVENTADOR SVJ XAGO | C24: V12 | D24: 6498 | E24: 759 | F24: 350 | G24: 2.9 | H24: 603000 | I24: Petrol | J24: 2 | K24: 720
A25: Nissan | B25: GT-R LM NISMO | C25: 3.0L Twin-Turbo V6 Hybrid | D25: 3000 | F25: 320 | G25: 3 | H25: 600000 | I25: Hybrid | J25: 2 | K25: 650
A26: Lamborghini | B26: AVENTADOR SVJ ROADSTER | C26: V12 | D26: 6498 | E26: 759 | F26: 350 | G26: 2.9 | H26: 573000 | I26: Petrol | J26: 2 | K26: 720
A27: Lamborghini | B27: AVENTADOR LP 780-4 ULTIMATE ROADSTER | C27: V12 | D27: 6498 | E27: 769 | F27: 355 | G27: 2.8 | H27: 573000 | I27: Petrol | J27: 2 | K27: 720
A28: Lamborghini | B28: AVENTADOR ULTIMAE | C28: V12 | D28: 6498 | E28: 769 | F28: 355 | G28: 2.8 | H28: 545000 | I28: Petrol | J28: 2 | K28: 720
A29: Lamborghini | B29: AVENTADOR LP 780-4 ULTIMATE | C29: V12 | D29: 6498 | E29: 769 | F29: 355 | G29: 2.8 | H29: 545000 | I29: Petrol | J29: 2 | K29: 720
A30: Lamborghini | B30: AVENTADOR SVJ | C30: V12 | D30: 6498 | E30: 759 | F30: 350 | G30: 2.8 | H30: 518000 | I30: Petrol | J30: 2 | K30: 720
A31: Rolls Royce | B31: PHANTOM CELESTIAL | C31: V12 | D31: 6749 | E31: 563 | F31: 250 | G31: 5.3 | H31: 515000 | I31: Petrol | J31: 5 | K31: 900
A32: Rolls Royce | B32: PHANTOM EXTENDED | C32: V12 | D32: 6749 | E32: 563 | F32: 250 | G32: 5.3 | H32: 500000 | I32: Petrol | J32: 5 | K32: 900
A33: Ford | B33: GT | C33: 3.5L Twin-Turbo V6 | D33: 3500 | E33: 660 | F33: 348 | G33: 3 | H33: 500000 | I33: Petrol | J33: 2 | K33: 746
A34: McLaren | B34: Mclaren 720s | C34: V8 | D34: 3994 | E34: 710 | F34: 341 | G34: 2.9 | H34: 499000 | I34: Petrol | J34: 2 | K34: 770
A35: Rolls Royce | B35: PHATOM ORCHID | C35: V12 | D35: 6749 | E35: 563 | F35: 250 | G35: 5.3 | H35: 495000 | I35: Petrol | J35: 5 | K35: 900
A36: Lamborghini | B36: AVENTADOR SV | C36: V12 | D36: 6498 | E36: 740 | F36: 350 | G36: 2.8 | H36: 493000 | I36: Petrol | J36: 2 | K36: 690
A37: Rolls Royce | B37: PHATOM TRANQUILITY | C37: V12 | D37: 6749 | E37: 563 | F37: 250 | G37: 5.3 | H37: 475000 | I37: Petrol | J37: 5 | K37: 900
... A99: Ferrari | B99: PORTOFINO M | C99: V8 | D99: 3900 | E99: 612 | F99: 320 | G99: 3.2 | H99: 220000 | I99: Petrol | J99: 4 | K99: 760
A100: Nissan | B100: GT-R NISMO | C100: 3.8L Twin-Turbo V6 | D100: 3799 | F100: 330 | G100: 2.9 | H100: 220000 | I100: Petrol | J100: 2 | K100: 652
A101: Nissan | B101: GT-R Egoist | C101: 3.8L Twin-Turbo V6 | D101: 3799 | F101: 315 | G101: 2.8 | H101: 220000 | I101: Petrol | J101: 2 | K101: 637
A102: Lamborghini | B102: URUS | C102: V8 | D102: 3996 | E102: 641 | F102: 305 | G102: 3.6 | H102: 211000 | I102: Petrol | J102: 5 | K102: 850
A103: Ferrari | B103: PORTOFINO | C103: V8 | D103: 3900 | E103: 592 | F103: 320 | G103: 3.2 | H103: 210000 | I103: Petrol | J103: 4 | K103: 760
A104: Aston Martin | B104: DB11 | C104: V12 | D104: 5204 | E104: 600 | F104: 322 | G104: 3.9 | H104: 208000 | I104: Petrol | J104: 4 | K104: 700
A105: Porsche | B105: 911 Turbo S Coupe | C105: 3.8L Twin-Turbo Flat-6 | D105: 3745 | E105: 640 | F105: 330 | G105: 2.7 | H105: 207000 | I105: Petrol | J105: 4 | K105: 800
A106: Porsche | B106: Panamera Turbo S E-Hybrid Sport Turismo | C106: 4.0L Twin-Turbo V8 + Electric Motor | D106: 3996 | E106: 690 | F106: 315 | G106: 3.2 | H106: 200200 | I106: Hybrid | J106: 4 | K106: 870
A107: Mercedes | B107: BENZ MAYBACH S 680 | C107: V12 | D107: 5980 | E107: 630 | F107: 250 | G107: 4.7 | H107: 200000 | I107: Petrol | J107: 5 | K107: 1000
...
